Workbook

Sheet Đọc trước
A1: ViLexTime — bản xem trước
A2: 1150 dòng QA · schema 1.0.0 (ADR 0003) · dựng từ commit 3ead9d8
A4: TRẠNG THÁI: CHƯA PHÁT HÀNH
A5: • Câu hỏi mới qua kiểm tự động; chưa qua người kiểm (review_status = unchecked).
A6: • Kiểm chéo Cohen κ trên 300 dòng: chưa gán nhãn (data/review/crosscheck_A.tsv, _B.tsv).
A7: • T5: chờ luật sư xét theo Điều 152 Luật BHVBQPPL.
A8: • Chưa chia dev/test (cột split rỗng).
A9: • Đáp án chuẩn lấy từ dữ liệu phiên bản, không do LLM viết.
A11: KHÔNG sửa dữ liệu trong file này. Repository là bản gốc; file này sinh lại bằng
A12: python scripts/review/export_excel.py
A14: CÁC CỘT (tab Dataset)
A15: Cột | B15: Ý nghĩa
A16: id | B16: Khoá dòng: nhóm, điều khoản, mốc hỏi
A17: group | B17: Nhóm T1–T6
A18: question | B18: Câu hỏi (LLM viết, đã qua kiểm tự động, chưa qua người)
A19: as_of | B19: Mốc thời gian câu hỏi được hỏi (YYYY-MM-DD)
A20: answer | B20: Đáp án chuẩn: nguyên văn điều khoản có hiệu lực tại as_of; rỗng khi không có đáp án
A21: answerable | B21: Có đáp án tại as_of không
A22: no_answer_reason | B22: Lý do không có đáp án (provision_repealed = điều khoản đã bị bãi bỏ)
A23: law_id | B23: Số hiệu văn bản chứa điều khoản
A24: citation | B24: Điều/Khoản/Điểm
A25: provision_path | B25: Vị trí trong cây văn bản
A26: lead_in | B26: Tiêu đề/câu dẫn của nút cha
... A41: T2 | B41: Cùng một câu hỏi, hỏi ở 2 mốc liền nhau - trước và sau ngày sửa đổi

Sheet Dataset
A1: id | B1: group | C1: question | D1: as_of | E1: answer | F1: answerable | G1: no_answer_reason | H1: law_id | I1: citation | J1: provision_path | K1: lead_in | L1: document_title | M1: version_id | N1: valid_from | O1: valid_to | P1: num_versions | Q1: amendments | R1: retroactive | S1: source_url | T1: review_status | U1: split
A2: vilextime:T1:provision:0071e540-2cd0-11f1-af56-05272582deeb:2021-08-17 | B2: T1 | C2: Trong lĩnh vực quan trắc môi trường, tổ chức tham gia quan trắc phải xây dựng hệ thống quản lý chất lượng nội bộ theo chuẩn nào và dưới hình thức gì? | D2: 2021-08-17 | E2: 1. Tổ chức tham gia hoạt động quan trắc môi trường phải áp dụng hệ thống quản lý chất lượng theo Tiêu chuẩn ISO/IEC 17025:2017 hoặc tương đương để xây dựng hệ thống quản lý chất lượng nội bộ nhằm đảm bảo chất lượng kết quả quan trắc. Hệ thống quản lý chất lượng phải thiết lập bằng văn bản và phổ biến cho người lao động để biết và thực hiện. Hệ thống quản lý chất lượng phải được duy trì và liên tục cải tiến phù hợp với phạm vi hoạt động, bảo đảm tính khách quan và chính xác của các kết quả quan trắc. | F2: có | H2: 10/2021/TT-BTNMT | I2: Khoản 1 Điều 20 | J2: Chương V › Điều 20 › Khoản 1 | K2: Điều 20. Hệ thống quản lý chất lượng quan trắc môi trường | L2: Thông tư số 10/2021/TT-BTNMT Quy định kỹ thuật quan trắc môi trường và quản lý thông tin, dữ liệu quan trắc chất lượng môi trường | M2: version:0071e540-2cd0-11f1-af56-05272582deeb:1 | N2: 2021-08-16 | P2: 1 | S2: https://vbpl.vn/TW/Pages/vbpq-toanvan.aspx?ItemID=149001 | T2: unchecked | V2: verified
A3: vilextime:T1:provision:0874e970-3425-11f1-9e65-619eaa3c24f9:2004-10-02 | B3: T1 | C3: Trong lĩnh vực chứng khoán, hành vi của tổ chức phát hành liên quan đến việc thông báo phát hành trên phương tiện thông tin đại chúng bị coi là vi phạm khi nào? | D3: 2004-10-02 | E3: đ) Thông báo phát hành chứng khoán trên các phương tiện thông tin đại chúng không đúng nội dung, thời hạn và thời gian theo quy định; | F3: có | H3: 161/2004/NĐ-CP | I3: Điểm đ Khoản 1 Điều 8 | J3: Chương 2 › Mục 1 › Điều 8 › Khoản 1 › Điểm đ | K3: 1. Phạt tiền từ 10.000.000 đồng đến 20.000.000 đồng đối với mỗi tổ chức phát hành, tổ chức tư vấn phát hành thực hiện một trong những hành vi vi phạm sau: | L3: Nghị định số 161/2004/NĐ-CP Về xử phạt vi phạm hành chính trong lĩnh vực chứng khoán và thị trường chứng khoán | M3: version:0874e970-3425-11f1-9e65-619eaa3c24f9:1 | N3: 2004-10-01 | P3: 1 | S3: https://vanban.chinhphu.vn/default.aspx?docid=13409&pageid=27160 | T3: unchecked | V3: suspected: valid_to
A4: vilextime:T1:provision:087c6ee0-eab8-11f0-ae57-61568758dbb7#k6#c:2014-01-16 | B4: T1 | C4: Nếu một tổ chức được cấp phép cung cấp dịch vụ chứng thực chữ ký số công cộng nhưng không đặt hệ thống thiết bị tại Việt Nam, thì bị phạt tiền ở mức nào? | D4: 2014-01-16 | E4: c) Không đặt ở Việt Nam hệ thống thiết bị cung cấp dịch vụ chứng thực chữ ký số của tổ chức được Bộ Thông tin và Truyền thông cấp giấy phép cung cấp dịch vụ chứng thực chữ ký số công cộng hoặc giấy chứng nhận đủ điều kiện bảo đảm an toàn cho chữ ký số chuyên dùng; | F4: có | H4: 174/2013/NĐ-CP | I4: Điểm c Khoản 6 Điều 57 | J4: Chương IV › Mục 2 › Điều 57 › Khoản 6 › Điểm c | K4: 6. Phạt tiền từ 60.000.000 đồng đến 80.000.000 đồng đối với một trong các hành vi sau đây: | L4: Nghị định số 174/2013/NĐ-CP Quy định xử phạt vi phạm hành chính trong lĩnh vực bưu chính, viễn thông, công nghệ thông tin và tần số vô tuyến điện | M4: version:087c6ee0-eab8-11f0-ae57-61568758dbb7#k6#c:1 | N4: 2014-01-15 | O4: 2020-04-15 | P4: 1 | S4: https://chinhphu.vn/default.aspx?docid=170929&pageid=27160 | T4: unchecked | V4: suspected: question-answer
A5: vilextime:T1:provision:0991e63e-eb76-11f0-a570-0d4a4dc3d190#k2:1996-12-18 | B5: T1 | C5: Pháp luật về dầu khí quy định giới hạn phạm vi khoan của tổ chức, cá nhân trong khi tiến hành khoan như thế nào? | D5: 1996-12-18 | E5: 2. Không được khoan ra ngoài diện tích hợp đồng dầu khí. | F5: có | H5: 84-CP | I5: Khoản 2 Điều 13 | J5: Chương II › Điều 13 › Khoản 2 | K5: Điều 13. Trong khi tiến hành khoan, Tổ chức, cá nhân phải thực hiện các quy định sau đây: | L5: Nghị định số 84-CP Quy định chi tiết việc thi hành Luật Dầu khí | M5: version:0991e63e-eb76-11f0-a570-0d4a4dc3d190#k2:1 | N5: 1996-12-17 | O5: 2000-09-27 | P5: 1 | S5: https://vanban.chinhphu.vn/default.aspx?docid=3241&pageid=27160 | T5: unchecked | V5: verified
A6: vilextime:T1:provision:09e3e960-2759-11f1-aa6b-33c42ee76deb:2007-08-08 | B6: T1 | C6: Pháp luật về đăng ký và quản lý hành nghề kế toán quy định việc xóa tên người hành nghề kế toán khi đăng ký hành nghề không đúng thực tế như thế nào? | D6: 2007-08-08 | E6: c) Thực tế không hành nghề kế toán nhưng vẫn cố tình đăng ký hành nghề kế toán; hoặc đồng thời đăng ký hành nghề kế toán ở hai nơi. | F6: có | H6: 72/2007/TT-BTC | I6: Điểm c Khoản 2 | J6: Khoản 2 › Điểm c | K6: 2.9. Người hành nghề kế toán bị xóa tên trong danh sách đăng ký hành nghề kế toán trong các trường hợp sau: | L6: Thông tư số 72/2007/TT-BTC Hướng dẫn việc đăng ký và quản lý hành nghề kế toán | M6: version:09e3e960-2759-11f1-aa6b-33c42ee76deb:1 | N6: 2007-08-07 | O6: 2017-01-01 | P6: 1 | S6: https://vanban.chinhphu.vn/default.aspx?docid=30537&pageid=27160 | T6: unchecked | V6: verified
A7: vilextime:T1:provision:0a0950ec-df47-11f0-8d4e-473dd4fe84eb:2019-03-09 | B7: T1 | C7: Nếu một nhà xuất khẩu dùng thùng, bao bì chỉ để bảo vệ hàng trong lúc vận chuyển, thì loại vật liệu này được định nghĩa như thế nào trong quy tắc xuất xứ hàng hóa theo Hiệp định CPTPP? | D7: 2019-03-09 | E7: 9. Vật liệu đóng gói và bao bì đóng gói để vận chuyển là hàng hóa được sử dụng để bảo vệ một sản phẩm trong suốt quá trình vận chuyển sản phẩm đó mà không phải là vật liệu đóng gói và bao gói chứa đựng hàng hóa dùng để bán lẻ. | F7: có | H7: 03/2019/TT-BCT | I7: Khoản 9 Điều 3 | J7: Chương I › Điều 3 › Khoản 9 | K7: Theo quy định tại Thông tư này, các thuật ngữ dưới đây được hiểu như sau: | L7: Thông tư số 03/2019/TT-BCT quy định Quy tắc xuất xứ hàng hóa trong Hiệp định Đối tác Toàn diện và Tiến bộ xuyên Thái Bình Dương | M7: version:0a0950ec-df47-11f0-8d4e-473dd4fe84eb:1 | N7: 2019-03-08 | P7: 1 | S7: https://vanban.chinhphu.vn/default.aspx?docid=196497&pageid=27160 | T7: unchecked | V7: verified
A8: vilextime:T1:provision:0ad14760-3261-11f1-803c-c1123978731e:2025-09-11 | B8: T1 | C8: Thời hạn và thẩm quyền quyết định dừng sử dụng vốn ODA, vốn vay ưu đãi đối với một chương trình, dự án được xác định ra sao? | D8: 2025-09-11 | E8: đ) Trong thời gian 15 ngày làm việc kể từ ngày nhận đủ hồ sơ hợp lệ, Thủ tướng Chính phủ quyết định dừng sử dụng vốn ODA, vốn vay ưu đãi nước ngoài đối với chương trình, dự án. | F8: có | H8: 242/2025/NĐ-CP | I8: Điểm đ Khoản 3 Điều 23 | J8: Chương II › Mục 3 › Điều 23 › Khoản 3 › Điểm đ | K8: 3. Hồ sơ, nội dung, thời gian quyết định dừng sử dụng vốn ODA, vốn vay ưu đãi: | L8: Nghị định số 242/2025/NĐ-CP Về quản lý và sử dụng vốn hỗ trợ phát triển chính thức (ODA) và vôn vay ưu đãi nước ngoài | M8: version:0ad14760-3261-11f1-803c-c1123978731e:1 | N8: 2025-09-10 | P8: 1 | S8: https://vanban.chinhphu.vn/?classid=1&docid=215266&orggroupid=2&pageid=27160 | T8: unchecked | V8: suspected: valid_to
A9: vilextime:T1:provision:0d5d0f9a-eb7c-11f0-a089-512bf9be00b3:2019-04-02 | B9: T1 | C9: Yêu cầu bảo trì đối với dầm, tường và cấu kiện bằng bê tông, gạch xây của công trình kiến trúc đường sắt được xác định ra sao trong tiêu chí giám sát, nghiệm thu bảo trì kết cấu hạ tầng đường sắt? | D9: 2019-04-02 | E9: c) Dầm, tường và các cấu kiện khác bằng bê tông cốt thép, bê tông, gạch xây: phải đảm bảo hoạt động, thoát nước tốt và được kiểm tra, theo dõi thường xuyên; | F9: có | H9: 06/2019/TT-BGTVT | I9: Điểm c Khoản 7 Điều 5 | J9: Chương II › Điều 5 › Khoản 7 › Điểm c | K9: 7. Đối với công trình kiến trúc: | L9: Thông tư số 06/2019/TT-BGTVT Quy định tiêu chí giám sát, nghiệm thu kết quả bảo trì tài sản kết cấu hạ tầng đường sắt quốc gia theo chất lượng thực hiện và chế độ, quy trình bảo trì tài sản kết cấu hạ tầng đường sắt quốc gia | M9: version:0d5d0f9a-eb7c-11f0-a089-512bf9be00b3:1 | N9: 2019-04-01 | P9: 1 | S9: https://vbpl.vn/van-ban/chi-tiet/thong-tu-so-06-2019-tt-bgtvt-quy-dinh-tieu-chi-giam-sat-nghiem-thu-ket-qua-bao-tri-tai-san-ket-cau-ha-tang-duong-sat-quoc-gia-theo-chat-luong-thuc-hien-va-che-do-quy-trinh-bao-tri-tai-san-ket-cau-ha-tang-duong-sat-quoc-gia--137556?tabs=thuoc-tinh | T9: unchecked | V9: verified
A10: vilextime:T1:provision:0ef06970-eacc-11f0-a885-a3ee6fe058ee:2016-01-02 | B10: T1 | C10: Theo quy định về kiểm toán nhà nước, Tổng Kiểm toán nhà nước có quyền kiến nghị những người đứng đầu cơ quan nào? | D10: 2016-01-02 | E10: 4. Kiến nghị Bộ trưởng, Thủ trưởng cơ quan ngang bộ, Thủ trưởng cơ quan thuộc Chính phủ, các cơ quan khác ở trung ương, Chủ tịch Ủy ban nhân dân tỉnh, thành phố trực thuộc trung ương, thủ trưởng cấp trên trực tiếp của đơn vị được kiểm toán xử lý theo thẩm quyền đối với cơ quan, tổ chức, cá nhân có hành vi cản trở hoạt động kiểm toán của Kiểm toán nhà nước; cung cấp thông tin, tài liệu sai sự thật cho Kiểm toán nhà nước; không thực hiện hoặc thực hiện không đầy đủ, kịp thời kết luận, kiến nghị của Kiểm toán nhà nước. Trường hợp kết luận, kiến nghị của Kiểm toán nhà nước không được giải quyết hoặc giải quyết không đầy đủ thì Tổng Kiểm toán nhà nước kiến nghị người có thẩm quyền xem xét, xử lý theo quy định của pháp luật. | F10: có | H10: 81/2015/QH13 | I10: Khoản 4 Điều 14 | J10: Chương II › Mục 2 › Điều 14 › Khoản 4 | K10: Điều 14. Quyền hạn của Tổng Kiểm toán nhà nước | L10: Luật Kiểm toán nhà nước số 81/2015/QH13 | M10: version:0ef06970-eacc-11f0-a885-a3ee6fe058ee:1 | N10: 2016-01-01 | P10: 1 | S10: https://vbpl.vn/van-ban/chi-tiet/x--70801 | T10: unchecked | V10: verified
A11: vilextime:T1:provision:0f4a76b0-ead4-11f0-986e-6fcc4fd049ad:2007-01-17 | B11: T1 | C11: Theo quy định về tín dụng đầu tư và tín dụng xuất khẩu của Nhà nước, lãi suất cho vay được xác định vào thời điểm nào và có thay đổi trong thời hạn vay không? | D11: 2007-01-17 | E11: 5. Lãi suất cho vay được xác định tại thời điểm ký hợp đồng tín dụng lần đầu tiên và không thay đổi cho cả thời hạn vay vốn. | F11: có | H11: 151/2006/NĐ-CP | I11: Khoản 5 Điều 10 | J11: Chương II › Mục 1 › Điều 10 › Khoản 5 | K11: Điều 10. Đồng tiền và lãi suất cho vay | L11: Nghị định số 151/2006/NĐ-CP Về tín dụng đầu tư và tín dụng xuất khẩu của Nhà nước | M11: version:0f4a76b0-ead4-11f0-986e-6fcc4fd049ad:1 | N11: 2007-01-16 | O11: 2011-10-20 | P11: 1 | S11: https://chinhphu.vn/default.aspx?docid=18915&pageid=27160 | T11: unchecked | V11: verified
A12: vilextime:T1:provision:0f6aad28-eb91-11f0-899c-6f62681cbf5d#k1#d:2011-12-27 | B12: T1 | C12: Khi một khu rừng đặc dụng chưa có ban quản lý, cơ quan nào được giao tổ chức lập quy hoạch cho khu rừng đó? | D12: 2011-12-27 | E12: d) Đối với những khu rừng đặc dụng chưa có ban quản lý, Sở Nông nghiệp và Phát triển nông thôn giao cho Chi cục Kiểm lâm tổ chức lập quy hoạch các khu rừng đặc dụng này. | F12: có | H12: 78/2011/TT-BNNPTNT | I12: Điểm d Khoản 1 Điều 2 | J12: Điều 2 › Khoản 1 › Điểm d | K12: 1. Quy hoạch khu rừng đặc dụng | L12: Thông tư số 78/2011/TT-BNNPTNT Quy định chi tiết thi hành Nghị định số 117/2010/NĐ-CP ngày 24/12/2010 của Chính phủ về tổ chức và quản lý hệ thống rừng đặc dụng | M12: version:0f6aad28-eb91-11f0-899c-6f62681cbf5d#k1#d:1 | N12: 2011-12-26 | O12: 2019-01-01 | P12: 1 | S12: https://vanban.chinhphu.vn/default.aspx?docid=153823&pageid=27160 | T12: unchecked | V12: verified
A13: vilextime:T1:provision:0f951378-eb7e-11f0-ad7d-19efec5eca1a#k3#d:2014-11-02 | B13: T1 | C13: Một người dân phát hiện thủ tục hành chính được giải quyết khác với thủ tục được niêm yết và đăng tải trên cơ sở dữ liệu quốc gia thì có thể phản ánh, kiến nghị với những cơ quan nào? | D13: 2014-11-02 | E13: d) Sự không thống nhất giữa thủ tục hành chính được giải quyết với thủ tục hành chính được niêm yết tại nơi giải quyết thủ tục hành chính và được đăng tải trên Cơ sở dữ liệu quốc gia. | F13: có | H13: 19/2014/TT-BTP | I13: Điểm d Khoản 3 Điều 10 | J13: Chương III › Điều 10 › Khoản 3 › Điểm d | K13: 3. Phản ánh, kiến nghị với Tổ chức Pháp chế các Bộ, cơ quan ngang Bộ, các cơ quan: Bảo hiểm Xã hội Việt Nam, Ngân hàng Chính sách Xã hội, Ngân hàng Phát triển Việt Nam; Sở Tư pháp các tỉnh, thành phố trực thuộc Trung ương hoặc Cục Kiểm soát thủ tục hành chính Bộ Tư pháp về những nội dung sau: | L13: Thông tư số 19/2014/TT-BTP Quy định về nhập, đăng tải, khai thác dữ liệu thủ tục hành chính trên Cơ sở dữ liệu quốc gia về thủ tục hành chính và quản lý Cơ sở dữ liệu quốc gia về thủ tục hành chính | M13: version:0f951378-eb7e-11f0-ad7d-19efec5eca1a#k3#d:1 | N13: 2014-11-01 | O13: 2018-03-20 | P13: 1 | S13: https://hethongphapluat.com/thong-tu-19-2014-tt-btp-ve-nhap-dang-tai-khai-thac-du-lieu-thu-tuc-hanh-chinh-tren-co-so-du-lieu-quoc-gia-ve-thu-tuc-hanh-chinh-va-quan-ly-co-so-du-lieu-quoc-gia-ve-thu-tuc-hanh-chinh-do-bo-truong-bo-tu-phap-ban-hanh.html?utm_source=chatgpt.com#google_vignette | T13: unchecked | V13: suspected: question-answer
A14: vilextime:T1:provision:0fb4e114-eb6d-11f0-89d0-c5c7e809c0cb:2018-01-02 | B14: T1 | C14: Trường hợp các cơ sở giam giữ áp dụng pháp luật về tạm giữ, tạm giam chưa thống nhất, cơ quan quản lý tạm giữ, tạm giam thuộc Bộ Công an, Bộ Quốc phòng có nhiệm vụ gì? | D14: 2018-01-02 | E14: c) Chỉ đạo nghiệp vụ, hướng dẫn áp dụng thống nhất pháp luật về thi hành tạm giữ, tạm giam; | F14: có | H14: 94/2015/QH13 | I14: Điểm c Khoản 1 Điều 12 | J14: Chương II › Điều 12 › Khoản 1 › Điểm c | K14: 1. Nhiệm vụ, quyền hạn của cơ quan quản lý tạm giữ, tạm giam thuộc Bộ Công an, Bộ Quốc phòng: | L14: Luật Thi hành tạm giữ, tạm giam số 94/2015/QH13 | M14: version:0fb4e114-eb6d-11f0-89d0-c5c7e809c0cb:1 | N14: 2018-01-01 | P14: 1 | S14: https://congbao.chinhphu.vn/van-ban/luat-so-94-2015-qh13-18437.htm | T14: unchecked | V14: suspected: valid_to
A15: vilextime:T1:provision:0fdffb50-2d40-11f1-ad9b-6dee35851177:2025-12-19 | B15: T1 | C15: Trong lĩnh vực chức danh nghề nghiệp bác sĩ y học dự phòng, nhiệm vụ về truyền thông giáo dục sức khỏe và quản lý sức khỏe cộng đồng gồm những việc gì? | D15: 2025-12-19 | E15: c) Tổ chức biên soạn nội dung và lập kế hoạch hướng dẫn công tác thông tin, giáo dục, truyền thông về bảo vệ, chăm sóc và nâng cao sức khỏe; đưa ra các biện pháp quản lý sức khỏe tại cộng đồng; | F15: có | H15: 41/2025/TT-BYT | I15: Điểm c Khoản 1 Điều 8 | J15: Chương III › Điều 8 › Khoản 1 › Điểm c | K15: 1. Nhiệm vụ: | L15: Thông tư số 41/2025/TT-BYT quy định mã số, tiêu chuẩn chức danh nghề nghiệp bác sĩ, bác sĩ y học dự phòng, y sĩ do Bộ trưởng Bộ Y tế ban hành | M15: version:0fdffb50-2d40-11f1-ad9b-6dee35851177:1 | N15: 2025-12-18 | P15: 1 | S15: Thông tư 41/2025/TT-BYT tiêu chuẩn chức danh nghề nghiệp bác sĩ bác sĩ y học dự phòng | T15: unchecked | V15: verified
A16: vilextime:T1:provision:102b73de-4247-11f1-b16e-79f7bcb231e7:2026-05-19 | B16: T1 | C16: Một công chứng viên gắn dấu thời gian vào lời chứng mà trước đó không kiểm tra chữ ký số của người tham gia giao dịch có hợp lệ hay không thì bị phạt tiền ở mức nào? | D16: 2026-05-19 | E16: s) Không kiểm tra tính hợp lệ của chữ ký số mà người tham gia giao dịch đã ký trước khi ký số, gắn dấu thời gian vào lời chứng. | F16: có | H16: 109/2026/NĐ-CP | I16: Điểm s Khoản 3 Điều 16 | J16: Chương II › Mục 3 › Điều 16 › Khoản 3 › Điểm s | K16: 3. Phạt tiền từ 7.000.000 đồng đến 10.000.000 đồng đối với một trong các hành vi sau: | L16: Nghị định 109/2026/NĐ-CP Quy định xử phạt vi phạm hành chính trong lĩnh vực bổ trợ tư pháp; hành chính tư pháp; hôn nhân và gia đình; thi hành án dân sự; phục hồi, phá sản doanh nghiệp, hợp tác xã | M16: version:102b73de-4247-11f1-b16e-79f7bcb231e7:1 | N16: 2026-05-18 | P16: 1 | S16: https://congbao.chinhphu.vn/van-ban/nghi-dinh-so-109-2026-nd-cp-469352.htm | T16: unchecked | V16: suspected: question-answer
A17: vilextime:T1:provision:102bc0a0-4247-11f1-8e2b-43ffd0f6b455:2026-05-19 | B17: T1 | C17: Hành vi sử dụng biển hiệu sai mẫu hoặc sai nội dung đăng ký hoạt động trong lĩnh vực bổ trợ tư pháp được xác định ra sao về mức xử phạt? | D17: 2026-05-19 | E17: e) Sử dụng biển hiệu không đúng mẫu hoặc nội dung biển hiệu không đúng giấy đăng ký hoạt động; | F17: có | H17: 109/2026/NĐ-CP | I17: Điểm e Khoản 1 Điều 17 | J17: Chương II › Mục 3 › Điều 17 › Khoản 1 › Điểm e | K17: 1. Phạt tiền từ 3.000.000 đồng đến 7.000.000 đồng đối với một trong các hành vi sau: | L17: Nghị định 109/2026/NĐ-CP Quy định xử phạt vi phạm hành chính trong lĩnh vực bổ trợ tư pháp; hành chính tư pháp; hôn nhân và gia đình; thi hành án dân sự; phục hồi, phá sản doanh nghiệp, hợp tác xã | M17: version:102bc0a0-4247-11f1-8e2b-43ffd0f6b455:1 | N17: 2026-05-18 | P17: 1 | S17: https://congbao.chinhphu.vn/van-ban/nghi-dinh-so-109-2026-nd-cp-469352.htm | T17: unchecked | V17: suspected: question-answer
A18: vilextime:T1:provision:12b26c34-eb71-11f0-a4ed-3975c8af2f8e#k2:2015-11-03 | B18: T1 | C18: Một đơn vị lập quy hoạch phát triển điện lực tỉnh có tuyến đường dây nhiều mạch thì định mức chi phí cho các mạch từ mạch thứ hai trở đi được điều chỉnh như thế nào? | D18: 2015-11-03 | E18: 2. Đối với đường dây điện có nhiều mạch, từ mạch thứ hai trở đi, định mức chi phí được tính bằng định mức tại Phụ lục I ban hành kèm theo Thông tư này nhân với hệ số 0,5. | F18: có | H18: 30/2015/TT-BCT | I18: Khoản 2 Điều 6 | J18: Chương II › Điều 6 › Khoản 2 | K18: Điều 6. Các hệ số điều chỉnh định mức chi phí Quy hoạch | L18: Thông tư số 30/2015/TT-BCT Quy định phương pháp xác định mức chi phí lập, thẩm định, công bố, điều chỉnh và quản lý Quy hoạch phát triển điện lực tỉnh, thành phố trực thuộc Trung ương và Quy hoạch phát triển thủy điện vừa và nhỏ | M18: version:12b26c34-eb71-11f0-a4ed-3975c8af2f8e#k2:1 | N18: 2015-11-02 | O18: 2024-12-31 | P18: 1 | S18: https://congbao.chinhphu.vn/van-ban/thong-tu-so-30-2015-tt-bct-17343.htm | T18: unchecked | V18: verified
A19: vilextime:T1:provision:135a9e3a-eb72-11f0-a7d6-6f3df067f0c1:2004-11-08 | B19: T1 | C19: Nếu văn hoá phẩm đồi trụy được nhập khẩu và lưu hành trên thị trường, Bộ Văn hoá - Thông tin có trách nhiệm tổ chức thực hiện những công tác phòng, chống mại dâm nào? | D19: 2004-11-08 | E19: 3. Tổ chức thực hiện công tác phòng, chống mại dâm trong hoạt động xuất khẩu, nhập khẩu, lưu hành trên thị trường các văn hoá phẩm đồi trụy; quản lý các cơ sở kinh doanh dịch vụ văn hoá. | F19: có | H19: 178/2004/NĐ-CP | I19: Khoản 3 Điều 28 | J19: Chương IV › Điều 28 › Khoản 3 | K19: Điều 28. Trách nhiệm của Bộ Văn hoá - Thông tin quy định tại khoản 1 Điều 34 của Pháp lệnh | L19: Nghị định số 178/2004/NĐ-CP Quy định chi tiết thi hành một số điều của Pháp lệnh Phòng, chống mại dâm | M19: version:135a9e3a-eb72-11f0-a7d6-6f3df067f0c1:1 | N19: 2004-11-07 | P19: 1 | S19: https://vanban.chinhphu.vn/default.aspx?docid=13489&pageid=27160 | T19: unchecked | V19: verified
A20: vilextime:T1:provision:1475c9a4-2d60-11f1-b2ad-3bbfacaea82c:2022-01-02 | B20: T1 | C20: Theo quy định về bảo vệ môi trường, các bộ và Ủy ban nhân dân cấp tỉnh có trách nhiệm gì về thống kê chỉ tiêu môi trường và báo cáo cho cơ quan nào? | D20: 2022-01-02 | E20: 3. Bộ, cơ quan ngang Bộ, Ủy ban nhân dân cấp tỉnh tổ chức công tác thống kê chỉ tiêu môi trường thuộc ngành, lĩnh vực, địa bàn quản lý; hằng năm báo cáo Bộ Tài nguyên và Môi trường các chỉ tiêu thống kê về môi trường. | F20: có | H20: 72/2020/QH14 | I20: Khoản 3 Điều 117 | J20: Chương IX › Mục 3 › Điều 117 › Khoản 3 | K20: Điều 117. Chỉ tiêu thống kê về môi trường | L20: Luật Bảo vệ môi trường số 72/2020/QH14 | M20: version:1475c9a4-2d60-11f1-b2ad-3bbfacaea82c:1 | N20: 2022-01-01 | P20: 1 | S20: https://vanban.chinhphu.vn/?classid=1&docid=202613&pageid=27160&typegroupid=3 | T20: unchecked | V20: verified
A21: vilextime:T1:provision:14f78dd0-2fff-11f1-9690-8315b14a55e2:2025-07-02 | B21: T1 | C21: Trường hợp một tổ chức chuyển dữ liệu cho bên khác, văn bản giao kết giữa hai bên phải xác định yêu cầu gì đối với việc bên nhận cung cấp tiếp dữ liệu đó? | D21: 2025-07-02 | E21: c) Yêu cầu ràng buộc đối với bên nhận dữ liệu về việc cung cấp dữ liệu đã được chuyển giao cho bên thứ ba; | F21: có | H21: 165/2025/NĐ-CP | I21: Điểm c Khoản 3 Điều 12 | J21: Chương II › Điều 12 › Khoản 3 › Điểm c | K21: 3. Văn bản giao kết giữa bên chuyển dữ liệu và bên nhận dữ liệu, phải xác định rõ: | L21: Nghị định số 165/2025/NĐ-CP Quy định chi tiết một số điều và biện pháp thi hành Luật Dữ liệu | M21: version:14f78dd0-2fff-11f1-9690-8315b14a55e2:1 | N21: 2025-07-01 | P21: 1 | S21: https://congbao.chinhphu.vn/van-ban/nghi-dinh-so-165-2025-nd-cp-45395.htm | T21: unchecked | V21: verified
A22: vilextime:T1:provision:156622a0-eae9-11f0-a37b-8b8c3d6f4421:2014-11-16 | B22: T1 | C22: Nếu một doanh nghiệp xếp hạng tín nhiệm xây dựng quy trình hoạt động, thì bước đánh giá khả năng trả nợ của tổ chức được xếp hạng phải gồm những công việc gì? | D22: 2014-11-16 | E22: d) Thu thập thông tin, phân tích, nhận định, xếp hạng về khả năng thực hiện đầy đủ, đúng hạn nghĩa vụ nợ của tổ chức được xếp hạng tín nhiệm; | F22: có | H22: 88/2014/NĐ-CP | I22: Điểm d Khoản 1 Điều 26 | J22: Chương III › Điều 26 › Khoản 1 › Điểm d | K22: 1. Doanh nghiệp xếp hạng tín nhiệm phải xây dựng quy trình hoạt động xếp hạng tín nhiệm bao gồm các bước cơ bản sau: | L22: Nghị định số 88/2014/NĐ-CP Quy định về dịch vụ xếp hạng tín nhiệm | M22: version:156622a0-eae9-11f0-a37b-8b8c3d6f4421:1 | N22: 2014-11-15 | P22: 1 | S22: https://vanban.chinhphu.vn/default.aspx?docid=176321&pageid=27160 | T22: unchecked | V22: verified
A23: vilextime:T1:provision:1766283a-df3f-11f0-8a4b-e980b4d5e909#k3#d:2005-06-09 | B23: T1 | C23: Trường hợp cần nâng cao khả năng tiếp cận kiến thức pháp luật và dịch vụ cho các gia đình, chiến lược xây dựng gia đình Việt Nam đề ra giải pháp gì về mạng lưới dịch vụ gia đình và cộng đồng? | D23: 2005-06-09 | E23: d) Mạng lưới dịch vụ gia đình và cộng đồng. Xây dựng, củng cố và nâng cao chất lượng hệ thống dịch vụ gia đình và cộng đồng; tạo điều kiện cho mọi gia đình tiếp cận được kiến thức pháp luật, văn hoá, y tế, giáo dục, khoa học kỹ thuật và phúc lợi xã hội. Xây dựng, củng cố và nâng cao hệ thống dịch vụ tư vấn về gia đình. Xây dựng và phát triển các loại hình dịch vụ về gia đình. | F23: có | H23: 106/2005/QĐ-TTg | I23: Điểm d Khoản 3 Điều 1 | J23: Điều 1 › Khoản 3 › Điểm d | K23: 3. Các giải pháp chủ yếu. | L23: Quyết định số 106/2005/QĐ-TTg Về việc phê duyệt Chiến lược xây dựng Gia đình Việt Nam giai đoạn 2005 - 2010 | M23: version:1766283a-df3f-11f0-8a4b-e980b4d5e909#k3#d:1 | N23: 2005-06-08 | O23: 2020-01-03 | P23: 1 | S23: https://thuvienphapluat.vn/van-ban/Van-hoa-Xa-hoi/Quyet-dinh-106-2005-QD-TTg-Chien-luoc-xay-dung-Gia-dinh-Viet-Nam-giai-doan-2005-2010-2480.aspx | T23: unchecked | V23: verified
A24: vilextime:T1:provision:189cfcfa-e175-11f0-a20b-737ea331ff00#k1#a:2017-06-16 | B24: T1 | C24: Một bộ, ngành trung ương lập kế hoạch đầu tư công trung hạn từ vốn ngân sách trung ương thì phải cập nhật và gửi nhu cầu, dự kiến kế hoạch cho cơ quan nào và bằng phương thức nào? | D24: 2017-06-16 | E24: a) Bộ, ngành trung ương và các Sở Kế hoạch và Đầu tư cập nhật chi tiết nhu cầu và dự kiến kế hoạch đầu tư công trung hạn, hàng năm và gửi Bộ Kế hoạch và Đầu tư trên Hệ thống. Thời gian và số liệu báo cáo của Bộ, ngành trung ương và địa phương được ghi nhận là thời gian và số liệu tại thời điểm gửi báo cáo cho Bộ Kế hoạch và Đầu tư trên Hệ thống. | F24: có | H24: 03/2017/TT-BKHĐT | I24: Điểm a Khoản 1 Điều 5 | J24: Chương II › Điều 5 › Khoản 1 › Điểm a | K24: 1. Đối với nguồn vốn ngân sách trung ương, vốn ODA và vốn vay ưu đãi của các nhà tài trợ nước ngoài; vốn tín dụng đầu tư phát triển của Nhà nước; vốn đầu tư từ nguồn thu để lại nhưng chưa đưa vào cân đối ngân sách nhà nước của Bộ, ngành trung ương: | L24: Thông tư số 03/2017/TT-BKHĐT quy định chế độ báo cáo việc lập, theo dõi và đánh giá thực hiện kế hoạch đầu tư công | M24: version:189cfcfa-e175-11f0-a20b-737ea331ff00#k1#a:1 | N24: 2017-06-15 | O24: 2024-10-16 | P24: 1 | S24: https://vanban.chinhphu.vn/default.aspx?docid=190009&pageid=27160 | T24: unchecked | V24: verified
A25: vilextime:T1:provision:1aaede10-2cb0-11f1-9616-d9eb3d88c179:2021-03-13 | B25: T1 | C25: Hình thức trình bày của tài liệu cập nhật kiến thức cho người hành nghề dịch vụ làm thủ tục về thuế được xác định ra sao? | D25: 2021-03-13 | E25: b) Tài liệu cập nhật kiến thức được trình bày dưới dạng văn bản hoặc dữ liệu điện tử. | F25: có | H25: 10/2021/TT-BTC | I25: Điểm b Khoản 2 Điều 19 | J25: Chương III › Điều 19 › Khoản 2 › Điểm b | K25: 2. Tài liệu cập nhật kiến thức | L25: Thông tư số 10/2021/TT-BTC Hướng dẫn quản lý hành nghề dịch vụ làm thủ tục về thuế | M25: version:1aaede10-2cb0-11f1-9616-d9eb3d88c179:1 | N25: 2021-03-12 | O25: 2026-07-24 | P25: 1 | S25: https://congbao.chinhphu.vn/van-ban/thong-tu-so-10-2021-tt-btc-33205.htm | T25: unchecked | V25: verified
A26: vilextime:T1:provision:1b3c3f68-eb87-11f0-a44b-2b764e784ab1:2001-04-02 | B26: T1 | C26: Khi doanh nghiệp bảo hiểm hoặc doanh nghiệp môi giới bảo hiểm tổ chức công tác kế toán, doanh nghiệp phải áp dụng chế độ kế toán nào? | D26: 2001-04-02 | E26: Doanh nghiệp bảo hiểm, doanh nghiệp môi giới bảo hiểm phải thực hiện chế độ kế toán áp dụng đối với kinh doanh bảo hiểm theo quy định của pháp luật về kế toán. | F26: có | H26: 24/2000/QH10 | I26: Điều 101 | J26: Chương V › Điều 101 | K26: VÀ BÁO CÁO TÀI CHÍNH | L26: Luật Kinh doanh bảo hiểm số 24/2000/QH10 | M26: version:1b3c3f68-eb87-11f0-a44b-2b764e784ab1:1 | N26: 2001-04-01 | P26: 1 | S26: https://vanban.chinhphu.vn/?docid=80498&pageid=27160 | T26: unchecked | V26: suspected: valid_to, lead_in
A27: vilextime:T1:provision:1bdb8a28-e15f-11f0-a6a9-fb5e10889a10#k2#d:2016-08-16 | B27: T1 | C27: Nội dung kiểm soát kiến trúc, cảnh quan trong thuyết minh đồ án quy hoạch chung khu chức năng đặc thù được xác định ra sao? | D27: 2016-08-16 | E27: d) Quy định kiểm soát về kiến trúc, cảnh quan trong khu quy hoạch: Định hướng phát triển các trục không gian, hành lang phát triển của khu quy hoạch, làm cơ sở xác định chỉ tiêu về mật độ dân cư, chỉ tiêu sử dụng đất quy hoạch, nguyên tắc phát triển đối với các khu chức năng của khu quy hoạch. | F27: có | H27: 12/2016/TT-BXD | I27: Điểm d Khoản 2 Điều 14 | J27: Chương II › Mục 3 › Điều 14 › Khoản 2 › Điểm d | K27: 2. Thuyết minh: Nội dung thuyết minh của đồ án quy hoạch chung xây dựng khu chức năng đặc thù gồm: | L27: Thông tư số 12/2016/TT-BXD Quy định về hồ sơ của nhiệm vụ và đồ án quy hoạch xây dựng vùng, quy hoạch đô thị và quy hoạch xây dựng khu chức năng đặc thù | M27: version:1bdb8a28-e15f-11f0-a6a9-fb5e10889a10#k2#d:1 | N27: 2016-08-15 | O27: 2023-01-01 | P27: 1 | S27: https://congbao.chinhphu.vn/van-ban/thong-tu-so-12-2016-tt-bxd-20428.htm | T27: unchecked | V27: verified
A28: vilextime:T1:provision:20737d10-2c88-11f1-824c-8fedf1153f0a:2009-08-15 | B28: T1 | C28: Nếu một doanh nghiệp sản xuất hàng hóa thuộc diện tăng cường quản lý chất lượng muốn chứng minh hệ thống quản lý chất lượng đạt chuẩn, thì việc chứng nhận phải theo tiêu chuẩn nào và do ai thực hiện? | D28: 2009-08-15 | E28: 5. Chứng nhận hệ thống quản lý chất lượng phù hợp tiêu chuẩn TCVN ISO 9001 hoặc tiêu chuẩn ISO 9001 Việc chứng nhận hệ thống quản lý chất lượng do tổ chức chứng nhận độc lập thực hiện nhằm chứng tỏ doanh nghiệp có hệ thống quản lý chất lượng phù hợp tiêu chuẩn TCVN ISO 9001 hoặc tiêu chuẩn ISO 9001. | F28: có | H28: 19/2009/TT-BKHCN | I28: Khoản 5 Điều 4 | J28: Chương II › Điều 4 › Khoản 5 | K28: Điều 4. Các biện pháp quản lý bổ sung Căn cứ vào tình hình thực tế sản xuất, nhập khẩu, lưu thông trên thị trường và nhu cầu quản lý, Bộ quản lý ngành, lĩnh vực ban hành văn bản quy định tiêu chí, lựa chọn một hoặc các biện pháp quản lý bổ sung thích hợp dưới đây để áp dụng cho từng loại sản phẩm, hàng hóa thuộc nhóm 2 hoặc sản phẩm, hàng hóa không thuộc nhóm 2 trong phạm vi được phân công quản lý: | L28: Thông tư số 19/2009/TT-BKHCN Quy định các biện pháp quản lý chất lượng đối với sản phẩm, hàng hóa cần tăng cường quản lý trước khi đưa ra lưu thông trên thị trường | M28: version:20737d10-2c88-11f1-824c-8fedf1153f0a:1 | N28: 2009-08-14 | P28: 1 | S28: https://chinhphu.vn/default.aspx?docid=90562&pageid=27160 | T28: unchecked | V28: verified
A29: vilextime:T1:provision:20f2564a-df43-11f0-b138-d581a4eb2b50#k3:2010-03-02 | B29: T1 | C29: Trường hợp một cơ sở gây ô nhiễm môi trường nghiêm trọng bị xử phạt, cơ sở đó bị buộc áp dụng biện pháp khắc phục hậu quả nào và trong thời hạn do ai ấn định? | D29: 2010-03-02 | E29: 3. Biện pháp khắc phục hậu quả: Buộc trong thời hạn do người có thẩm quyền xử phạt ấn định trong quyết định xử phạt vi phạm hành chính phải thực hiện các biện pháp khắc phục tình trạng ô nhiễm, phục hồi môi trường do các hành vi vi phạm quy định tại Điều này gây ra. | F29: có | H29: 117/2009/NĐ-CP | I29: Khoản 3 Điều 15 | J29: Chương II › Mục 1 › Điều 15 › Khoản 3 | K29: Điều 15. Vi phạm các quy định về bảo vệ môi trường đối với cơ sở thuộc danh mục các cơ sở gây ô nhiễm môi trường nghiêm trọng, cơ sở sản xuất, kinh doanh, dịch vụ bị áp dụng hình thức buộc di dời. | L29: Nghị định số 117/2009/NĐ-CP Về xử lý vi phạm pháp luật trong lĩnh vực bảo vệ môi trường | M29: version:20f2564a-df43-11f0-b138-d581a4eb2b50#k3:1 | N29: 2010-03-01 | O29: 2013-12-30 | P29: 1 | S29: https://vanban.chinhphu.vn/default.aspx?docid=92587 | T29: unchecked | V29: verified
A30: vilextime:T1:provision:21c3f428-eb70-11f0-802c-c99b808dc615#k1:2016-05-03 | B30: T1 | C30: Ban chỉ đạo chương trình, dự án sử dụng vốn ODA và vốn vay ưu đãi được xác định ra sao về cơ quan thành lập và thành phần tham gia? | D30: 2016-05-03 | E30: 1. Ban chỉ đạo chương trình, dự án sử dụng vốn ODA, vốn vay ưu đãi (sau đây gọi là “Ban chỉ đạo”) là một tổ chức được thành lập bởi cơ quan chủ quản chương trình, dự án sử dụng vốn ODA, vốn vay ưu đãi (sau đây gọi là “chương trình, dự án”) với sự tham gia của đại diện có thẩm quyền của cơ quan có liên quan để chỉ đạo, phối hợp, giám sát thực hiện chương trình, dự án. Trong một số trường hợp cần thiết, trên cơ sở thỏa thuận với nhà tài trợ nước ngoài, Ban chỉ đạo có thể bao gồm đại diện của nhà tài trợ nước ngoài. | F30: có | H30: 16/2016/NĐ-CP | I30: Khoản 1 Điều 3 | J30: Chương I › Điều 3 › Khoản 1 | K30: Điều 3. Giải thích từ ngữ | L30: Nghị định số 16/2016/NĐ-CP Về quản lý và sử dụng vốn hỗ trợ phát triển chính thức (ODA) và vốn vay ưu đãi của các nhà tài trợ nước ngoài | M30: version:21c3f428-eb70-11f0-802c-c99b808dc615#k1:1 | N30: 2016-05-02 | O30: 2020-05-25 | P30: 1 | S30: https://congbao.chinhphu.vn/van-ban/nghi-dinh-so-16-2016-nd-cp-19303.htm | T30: unchecked | V30: verified
A31: vilextime:T1:provision:24898286-eb7f-11f0-86be-295007d963d9#k5:2004-10-02 | B31: T1 | C31: Trường hợp cơ quan có thẩm quyền quyết định rà soát việc áp dụng biện pháp chống bán phá giá, việc rà soát phải hoàn thành trong thời hạn bao lâu? | D31: 2004-10-02 | E31: 5. Thời hạn rà soát việc áp dụng biện pháp chống bán phá giá quy định tại khoản 1 và khoản 2 Điều này là không quá mười hai tháng, kể từ ngày có quyết định rà soát. | F31: có | H31: 20/2004/PL-UBTVQH11 | I31: Khoản 5 Điều 24 | J31: Chương IV › Điều 24 › Khoản 5 | K31: Điều 24. Rà soát việc áp dụng biện pháp chống bán phá giá | L31: Pháp lệnh số 20/2004/PL-UBTVQH11 Chống bán phá giá hàng hoá nhập khẩu vào Việt Nam | M31: version:24898286-eb7f-11f0-86be-295007d963d9#k5:1 | N31: 2004-10-01 | O31: 2018-01-01 | P31: 1 | S31: https://moit.gov.vn/van-ban-phap-luat/van-ban-phap-quy/-phap-lenh-ve-chong-ban-pha-gia-hang-hoa-nhap-khau-vao-viet-.html | T31: unchecked | V31: verified
A32: vilextime:T1:provision:2506a790-eb87-11f0-bc8c-7d7d6b7332ea#k2#c:2013-01-21 | B32: T1 | C32: Trường hợp tàu quân sự nước ngoài làm thủ tục nhập cảnh tại cảng Việt Nam, người làm thủ tục phải nộp cho Hải quan cửa khẩu cảng những giấy tờ nào? | D32: 2013-01-21 | E32: c) Nộp cho Hải quan cửa khẩu cảng: - 01 (một) bản chính Bản khai chung (Mẫu 3); - 01 (một) bản chính Danh sách thành viên (Mẫu 4); - 01 (một) bản chính Bản khai dự trữ của tàu (Mẫu 7); - 01 (một) bản chính Bản khai hành lý thành viên (Mẫu 8); - 01 (một) bản chính Bản kê khai hàng hóa (nếu có - Mẫu 5); - 01 (một) bản chính Bản khai hàng hóa nguy hiểm (nếu có - Mẫu 6); - 01 (một) bản sao hợp đồng sửa chữa hoặc thỏa thuận nguyên tắc sửa chữa. | F32: có | H32: 104/2012/NĐ-CP | I32: Điểm c Khoản 2 Điều 21 | J32: Chương III › Mục 1 › Điều 21 › Khoản 2 › Điểm c | K32: 2. Các loại giấy tờ người làm thủ tục phải nộp khi làm thủ tục nhập cảnh | L32: Nghị định số 104/2012/NĐ-CP Quy định đối với tàu quân sự nước ngoài đến nước Cộng hòa xã hội chủ nghĩa Việt Nam | M32: version:2506a790-eb87-11f0-bc8c-7d7d6b7332ea#k2#c:1 | N32: 2013-01-20 | O32: 2025-10-12 | P32: 1 | S32: https://chinhphu.vn/default.aspx?docid=164851&pageid=27160 | T32: unchecked | V32: verified
A33: vilextime:T1:provision:273af4d0-1db4-11f1-8ca4-fb91ecf6f674:2012-11-16 | B33: T1 | C33: Nếu một thương nhân nước ngoài không có hiện diện tại Việt Nam phải thông báo hoạt động trên phương tiện thông tin đại chúng, thì những loại báo nào được coi là phương tiện thông tin đại chúng phổ biến? | D33: 2012-11-16 | E33: 2. Các phương tiện thông tin đại chúng phổ biến bao gồm báo hình, báo tiếng, báo mạng, báo in được phát hành toàn quốc tại Việt Nam. | F33: có | H33: 28/2012/TT-BCT | I33: Khoản 2 Điều 11 | J33: Chương III › Điều 11 › Khoản 2 | K33: Điều 11. Thông báo hoạt động | L33: Thông tư số 28/2012/TT-BCT Quy định chi tiết việc đăng ký quyền xuất khẩu, quyền nhập khẩu của thương nhân nước ngoài không có hiện diện tại Việt Nam | M33: version:273af4d0-1db4-11f1-8ca4-fb91ecf6f674:1 | N33: 2012-11-15 | P33: 1 | S33: https://congbao.chinhphu.vn/van-ban/thong-tu-so-28-2012-tt-bct-16903.htm | T33: unchecked | V33: verified
A34: vilextime:T1:provision:2744c8d4-278c-11f1-93f1-6b9e4c555f4c:1999-05-24 | B34: T1 | C34: Trong lĩnh vực tiền lương của Tổng Công ty Điện lực Việt Nam, điều kiện áp dụng hệ số điều chỉnh tăng thêm tiền lương tối thiểu để tính đơn giá tiền lương được quy định ra sao? | D34: 1999-05-24 | E34: b. Điều kiện áp dụng hệ số điều chỉnh tăng thêm tiền lương tối thiểu: Việc áp dụng hệ số điều chỉnh tăng thêm tiền lương tối thiểu để tính đơn giá tiền lương của Tổng Công ty theo quy định tại Nghị định số 28/CP ngày 28/3/1997 của Chính phủ khi thực hiện đầy đủ các điều kiện sau: - Sản xuất, kinh doanh có lãi; - Bảo đảm thực hiện các khoản nộp ngân sách nhà nước theo đúng quy định của pháp luật; - Mỗi năm giảm tổn thất điện năng từ 0,2% - 0,3% so với chỉ tiêu kế hoạch được Hội đồng quản trị Tổng Công ty Điện lực Việt Nam phê duyệt (chỉ tiêu tổn thất điện được xây dựng trên cơ sở số thực hiện của năm trước liền kề). - Năng suất lao động bình quân của công nhân, viên chức ngành điện tính theo Kwh điện thương phẩm năm sau phải cao hơn năm trước liền kề. | F34: có | H34: 20/1999/TT-BLĐTBXH | I34: Điểm b | J34: Phần › Mục › Điểm b | K34: 1. Đơn giá tiền lương. | L34: Thông tư số 20/1999/TT-BLĐTBXH Hướng dẫn thực hiện Quyết định số 121/1999/QĐ-TTg ngày 08/5/1999 của Thủ tướng Chính phủ về tiền lương và thu nhập của Tổng Công ty Điện lực Việt Nam. | M34: version:2744c8d4-278c-11f1-93f1-6b9e4c555f4c:1 | N34: 1999-05-23 | O34: 2006-01-11 | P34: 1 | S34: https://thuvienphapluat.vn/van-ban/Lao-dong-Tien-luong/Thong-tu-20-1999-TT-BLDTBXH-tien-luong-va-thu-nhap-cua-Tong-Cong-ty-Dien-luc-Viet-Nam-huong-dan-thuc-hien-Quyet-dinh-121-1999-QD-TTg-45679.aspx?utm_source=chatgpt.com | T34: unchecked | V34: suspected: valid_to
A35: vilextime:T1:provision:28de5a78-eb7f-11f0-b54b-5748bc951531#k1:2004-07-02 | B35: T1 | C35: Trường hợp quy hoạch một khu nhà chung cư, đất khu chung cư theo pháp luật đất đai bao gồm những loại đất nào? | D35: 2004-07-02 | E35: 1. Đất khu chung cư bao gồm đất để xây dựng nhà chung cư, xây dựng các công trình trực tiếp phục vụ đời sống của những hộ trong nhà chung cư theo quy hoạch xây dựng đã được cơ quan nhà nước có thẩm quyền xét duyệt. | F35: có | H35: 13/2003/QH11 | I35: Khoản 1 Điều 85 | J35: Chương III › Mục 3 › Điều 85 › Khoản 1 | K35: Điều 85. Đất xây dựng khu chung cư | L35: Luật Đất đai số 13/2003/QH11 | M35: version:28de5a78-eb7f-11f0-b54b-5748bc951531#k1:1 | N35: 2004-07-01 | O35: 2014-07-01 | P35: 1 | S35: https://vanban.chinhphu.vn/?classid=1&docid=32479&pageid=27160&typegroupid=3 | T35: unchecked | V35: verified
A36: vilextime:T1:provision:28e735ae-eb74-11f0-958c-6b1f0bf9f4f6:2023-07-29 | B36: T1 | C36: Khi chủ văn bằng bảo hộ giống cây trồng bị xử phạt vi phạm hành chính về trồng trọt, biện pháp khắc phục hậu quả nào có thể được áp dụng đối với văn bằng đó? | D36: 2023-07-29 | E36: d) Buộc nộp lại Bằng bảo hộ giống cây trồng cho cơ quan, người có thẩm quyền đã cấp Bằng bảo hộ giống cây trồng đó; | F36: có | H36: 31/2023/NĐ-CP | I36: Điểm d Khoản 3 Điều 4 | J36: Chương I › Điều 4 › Khoản 3 › Điểm d | K36: 3. Các biện pháp khắc phục hậu quả: | L36: Nghị định số 31/2023/NĐ-CP Quy định xử phạt vi phạm hành chính về Trồng trọt | M36: version:28e735ae-eb74-11f0-958c-6b1f0bf9f4f6:1 | N36: 2023-07-28 | P36: 1 | S36: https://congbao.chinhphu.vn/van-ban/nghi-dinh-so-31-2023-nd-cp-39585.htm | T36: unchecked | V36: suspected: valid_to
A37: vilextime:T1:provision:29828580-2cf7-11f1-abe4-6bb68cc00eff:2023-05-06 | B37: T1 | C37: Pháp luật về bảo hiểm vi mô quy định tổ chức tương hỗ bị lập biên bản vi phạm phải hạn chế hoạt động gì đối với hợp đồng bảo hiểm vi mô? | D37: 2023-05-06 | E37: a) Không được ký mới, gia hạn các hợp đồng bảo hiểm vi mô; | F37: có | H37: 21/2023/NĐ-CP | I37: Điểm a Khoản 1 Điều 15 | J37: Chương III › Mục 1 › Điều 15 › Khoản 1 › Điểm a | K37: 1. Kể từ ngày ký biên bản xác định vi phạm quy định đối với trường hợp quy định tại các điểm a và b khoản 1 Điều 14 Nghị định này, tổ chức tương hỗ cung cấp bảo hiểm vi mô phải thực hiện theo quy định sau đây: | L37: Nghị định số 21/2023/NĐ-CP Quy định về bảo hiểm vi mô | M37: version:29828580-2cf7-11f1-abe4-6bb68cc00eff:1 | N37: 2023-05-05 | P37: 1 | S37: https://congbao.chinhphu.vn/van-ban/nghi-dinh-so-21-2023-nd-cp-39292.htm | T37: unchecked | V37: verified
A38: vilextime:T1:provision:29b38ec0-2c82-11f1-a14d-8325351d2d6d:2022-11-16 | B38: T1 | C38: Trong lĩnh vực quản lý ngoại hối đối với vay nước ngoài, bên đi vay không có vốn đầu tư trực tiếp nước ngoài phải mở tài khoản gì và ở đâu? | D38: 2022-11-16 | E38: 3. Bên đi vay không phải là doanh nghiệp có vốn đầu tư trực tiếp nước ngoài phải mở tài khoản vay, trả nợ nước ngoài tại ngân hàng cung ứng dịch vụ tài khoản để thực hiện các giao dịch chuyển tiền liên quan đến khoản vay nước ngoài (rút vốn, trả nợ gốc, nợ lãi). Mỗi khoản vay nước ngoài chỉ được thực hiện qua 01 ngân hàng cung ứng dịch vụ tài khoản. Bên đi vay có thể dùng 01 tài khoản cho 01 hoặc nhiều khoản vay nước ngoài. Nội dung thu, chi của tài khoản này được quy định tại Điều 28 và Điều 29 Thông tư này. | F38: có | H38: 12/2022/TT-NHNN | I38: Khoản 3 Điều 26 | J38: Chương IV › Mục 1 › Điều 26 › Khoản 3 | K38: Điều 26. Tài khoản vay, trả nợ nước ngoài của bên đi vay | L38: Thông tư số 12/2022/TT-NHNN Hướng dẫn về quản lý ngoại hối đối với việc vay, trả nợ nước ngoài của doanh nghiệp | M38: version:29b38ec0-2c82-11f1-a14d-8325351d2d6d:1 | N38: 2022-11-15 | P38: 1 | S38: https://congbao.chinhphu.vn/van-ban/thong-tu-so-12-2022-tt-nhnn-38023.htm | T38: unchecked | V38: verified
A39: vilextime:T1:provision:29fe6800-3033-11f1-b559-9f1fcc43fa46:2018-10-16 | B39: T1 | C39: Khi lễ hội diễn ra, Bộ Công Thương có trách nhiệm chỉ đạo ngăn chặn những hoạt động buôn bán nào? | D39: 2018-10-16 | E39: 5. Bộ Công Thương có trách nhiệm chỉ đạo tăng cường kiểm tra, kiểm soát, ngăn chặn việc buôn bán, kinh doanh hàng giả, hàng kém chất lượng, hàng không rõ nguồn gốc trong hoạt động lễ hội. | F39: có | H39: 110/2018/NĐ-CP | I39: Khoản 5 Điều 19 | J39: Chương III › Điều 19 › Khoản 5 | K39: Điều 19. Trách nhiệm quản lý nhà nước về lễ hội của các bộ, ngành liên quan | L39: Nghị định số 110/2018/NĐ-CP Quy định về quản lý và tổ chức lễ hội | M39: version:29fe6800-3033-11f1-b559-9f1fcc43fa46:1 | N39: 2018-10-15 | P39: 1 | S39: https://vanban.chinhphu.vn/default.aspx?docid=194624&pageid=27160 | T39: unchecked | V39: verified
A40: vilextime:T1:provision:2b51f410-2d54-11f1-9c91-9929d4eca804:2012-04-01 | B40: T1 | C40: Khi một tổ chức tín dụng thực hiện nghiệp vụ chiết khấu giấy tờ có giá với Ngân hàng Nhà nước theo phương thức gián tiếp, giao dịch được thực hiện qua kênh nào? | D40: 2012-04-01 | E40: 2. Phương thức giao dịch gián tiếp: Các tổ chức tín dụng, chi nhánh ngân hàng nước ngoài giao dịch thông qua hệ thống mạng giao dịch nghiệp vụ thị trường tiền tệ theo hướng dẫn của Ngân hàng Nhà nước. | F40: có | H40: 01/2012/TT-NHNN | I40: Khoản 2 Điều 4 | J40: Chương I › Điều 4 › Khoản 2 | K40: Điều 4. Phương thức thực hiện nghiệp vụ chiết khấu | L40: Thông tư số 01/2012/TT-NHNN Quy định về chiết khấu giấy tờ có giá của Ngân hàng Nhà nước Việt Nam đối với tổ chức tín dụng, chi nhánh ngân hàng nước ngoài | M40: version:2b51f410-2d54-11f1-9c91-9929d4eca804:1 | N40: 2012-03-31 | P40: 1 | S40: https://congbao.chinhphu.vn/van-ban/thong-tu-so-01-2012-tt-nhnn-14785.htm | T40: unchecked | V40: verified
...

Sheet Thống kê
A1: Nhóm | B1: Mô tả | C1: Quota đề cương | D1: Số dòng | E1: Có đáp án | F1: Không có đáp án | G1: Chênh quota
A2: T1 | B2: Một phiên bản (điều khoản chưa từng bị sửa) | C2: 250 | D2: =COUNTIF(Dataset!$B$2:$B$1151,A2) -> 250 | E2: =COUNTIFS(Dataset!$B$2:$B$1151,A2,Dataset!$F$2:$F$1151,"có") -> 250 | F2: =D2-E2 -> 0 | G2: =D2-C2 -> 0
A3: T2 | B3: Hai phiên bản khác rõ (cặp tương phản trước/sau sửa đổi) | C3: 400 | D3: =COUNTIF(Dataset!$B$2:$B$1151,A3) -> 400 | E3: =COUNTIFS(Dataset!$B$2:$B$1151,A3,Dataset!$F$2:$F$1151,"có") -> 400 | F3: =D3-E3 -> 0 | G3: =D3-C3 -> 0
A4: T3 | B4: Chuỗi ≥ 3 phiên bản | C4: 200 | D4: =COUNTIF(Dataset!$B$2:$B$1151,A4) -> 200 | E4: =COUNTIFS(Dataset!$B$2:$B$1151,A4,Dataset!$F$2:$F$1151,"có") -> 200 | F4: =D4-E4 -> 0 | G4: =D4-C4 -> 0
A5: T4 | B5: Hai phiên bản gần giống (bẫy phiên bản cũ) | C5: 150 | D5: =COUNTIF(Dataset!$B$2:$B$1151,A5) -> 150 | E5: =COUNTIFS(Dataset!$B$2:$B$1151,A5,Dataset!$F$2:$F$1151,"có") -> 150 | F5: =D5-E5 -> 0 | G5: =D5-C5 -> 0
A6: T5 | B6: Hiệu lực trở về trước (chờ luật sư) | C6: 50 | D6: =COUNTIF(Dataset!$B$2:$B$1151,A6) -> 38 | E6: =COUNTIFS(Dataset!$B$2:$B$1151,A6,Dataset!$F$2:$F$1151,"có") -> 38 | F6: =D6-E6 -> 0 | G6: =D6-C6 -> -12
A7: T6 | B7: Hết hiệu lực một phần ở cấp khoản, điểm | C7: 100 | D7: =COUNTIF(Dataset!$B$2:$B$1151,A7) -> 112 | E7: =COUNTIFS(Dataset!$B$2:$B$1151,A7,Dataset!$F$2:$F$1151,"có") -> 56 | F7: =D7-E7 -> 56 | G7: =D7-C7 -> 12
A8: Tổng | C8: =SUM(C2:C7) -> 1150 | D8: =SUM(D2:D7) -> 1150 | E8: =SUM(E2:E7) -> 1094 | F8: =SUM(F2:F7) -> 56 | G8: =SUM(G2:G7) -> 0
A10: T6 nhận phần T5 thiếu (T5 chờ luật sư) để giữ tổng 1.150 — quyết định trong plan phase-4.
